<?xml version="1.0"?>
<!-- Copyright (c) 2016 The UUV Simulator Authors.
     All rights reserved.

     Licensed under the Apache License, Version 2.0 (the "License");
     you may not use this file except in compliance with the License.
     You may obtain a copy of the License at

       http://www.apache.org/licenses/LICENSE-2.0

     Unless required by applicable law or agreed to in writing, software
     distributed under the License is distributed on an "AS IS" BASIS,
     WITHOUT WARRANTIES OR CONDITIONS OF ANY KIND, either express or implied.
     See the License for the specific language governing permissions and
     limitations under the License.
-->
<robot xmlns:xacro="http://www.ros.org/wiki/xacro" >
  <!-- Import macro files -->
  <xacro:include filename="$(find uuv_descriptions)/urdf/common.urdf.xacro" />
  <xacro:include filename="$(find uuv_sensor_ros_plugins)/urdf/sensor_snippets.xacro"/>
  <xacro:include filename="$(find uuv_gazebo_ros_plugins)/urdf/snippets.xacro"/>

  <!-- Properties -->
  <xacro:property name="mass" value="56.0"/>
  <xacro:property name="fluid_density" value="1024.0"/>
  <xacro:property name="gravity" value="9.81"/>
  <xacro:property name="cob" value="0 0 0"/>
  <xacro:property name="cog" value="0 0 0.0054"/>

  <xacro:property name="visual_mesh_file" value="file://$(find uuv_kinematics_description)/mesh/uuv/uuv_body.dae" />
  <xacro:property name="collision_mesh_file" value="file://$(find uuv_kinematics_description)/mesh/uuv/uuv_collision.dae" />
  <xacro:property name="left_prop_mesh_file" value="file://$(find uuv_kinematics_description)/mesh/uuv/uuv_left_propeller.dae" />
  <xacro:property name="right_prop_mesh_file" value="file://$(find uuv_kinematics_description)/mesh/uuv/uuv_right_propeller.dae" />

  <xacro:macro name="uuv_kinematics_base" params="namespace debug inertial_reference_frame">
    <!-- Base_link of the model -->
    <link name="${namespace}/base_link">
      <visual>
        <origin xyz="0 0 0" rpy="0 0 -${0.5*pi}" />
        <geometry>
          <mesh filename="${visual_mesh_file}" scale="1 1 1" />
        </geometry>
      </visual>
      <collision>
        <origin xyz="0 0 0" rpy="0 0 -${0.5*pi}" />
        <geometry>
          <mesh filename="${collision_mesh_file}" scale="1 1 1" />
        </geometry>
      </collision>
      <inertial>
        <mass value="${mass}"/>
        <origin xyz="0 0 0" rpy="0 0 0" />
        <inertia ixx="0.3048" ixy="0" ixz="0" iyy="13.976" iyz="0" izz="13.976" />
      </inertial>
    </link>

    <!-- Dummy propeller plugin properties (rotorConstant = 0) -->
    <!-- This is for topics used to visualize the propeller roatation  -->
    <xacro:property name="dummy_plugin_properties_for_visual_rotation">
      <dynamics>
        <type>FirstOrder</type>
        <timeConstant>0.0</timeConstant>
      </dynamics>
      <conversion>
        <type>Basic</type>
        <rotorConstant>0.0</rotorConstant>
      </conversion>
    </xacro:property>
    <xacro:property name="dummy_link_properties_for_visual_rotation">
      <xacro:box_inertial x="0" y="0" z="0" mass="0.00001">
        <origin xyz="0 0 0" rpy="0 0 0"/>
      </xacro:box_inertial>
      <collision>
        <geometry>
          <cylinder length="0.000001" radius="0.000001"/>
        </geometry>
        <origin xyz="0 0 0" rpy="0 0 0"/>
      </collision>
    </xacro:property>

    <!-- First propeller -->
    <xacro:property name="thruster_id" value="1"/>
    <joint name="${namespace}/thruster_${thruster_id}_joint" type="continuous">
      <origin xyz="-0.558 -0.05 0" rpy="0 0 -${0.07*pi}"/>
      <axis xyz="1 0 0"/>
      <parent link="${namespace}/base_link"/>
      <child link="${namespace}/thruster_${thruster_id}"/>
    </joint>
    <link name="${namespace}/thruster_${thruster_id}">
      <xacro:insert_block name="dummy_link_properties_for_visual_rotation"/>
      <visual>
        <origin xyz="0.541 0.12 0" rpy="0 0 -${0.46*pi}"/>
        <geometry>
          <mesh filename="${right_prop_mesh_file}" scale="1 1 1"/>
        </geometry>
      </visual>
    </link>
    <gazebo>
      <plugin name="${namespace}_${thruster_id}_thruster_model" filename="libuuv_thruster_ros_plugin.so">
        <linkName>${namespace}/thruster_${thruster_id}</linkName>
        <jointName>${namespace}/thruster_${thruster_id}_joint</jointName>
        <thrusterID>${thruster_id}</thrusterID>
        <xacro:insert_block name="dummy_plugin_properties_for_visual_rotation"/>
      </plugin>
    </gazebo>
    <gazebo reference="${namespace}/thruster_${thruster_id}">
      <selfCollide>false</selfCollide>
    </gazebo>

    <!-- Second propeller -->
    <xacro:property name="thruster_id" value="0"/>
    <joint name="${namespace}/thruster_${thruster_id}_joint" type="continuous">
      <origin xyz="-0.558 0.05 0" rpy="0 0 ${0.07*pi+pi}"/>
      <axis xyz="1 0 0"/>
      <parent link="${namespace}/base_link"/>
      <child link="${namespace}/thruster_${thruster_id}"/>
    </joint>
    <link name="${namespace}/thruster_${thruster_id}">
      <xacro:insert_block name="dummy_link_properties_for_visual_rotation"/>
      <visual>
        <origin xyz="-0.541 0.12 0" rpy="0 0 ${0.46*pi}"/>
        <geometry>
          <mesh filename="${left_prop_mesh_file}" scale="1 1 1"/>
        </geometry>
      </visual>
    </link>
    <gazebo>
      <plugin name="${namespace}_${thruster_id}_thruster_model" filename="libuuv_thruster_ros_plugin.so">
        <linkName>${namespace}/thruster_${thruster_id}</linkName>
        <jointName>${namespace}/thruster_${thruster_id}_joint</jointName>
        <thrusterID>${thruster_id}</thrusterID>
        <xacro:insert_block name="dummy_plugin_properties_for_visual_rotation"/>
      </plugin>
    </gazebo>
    <gazebo reference="${namespace}/thruster_${thruster_id}">
      <selfCollide>false</selfCollide>
    </gazebo>

    <!-- Kinematics Plugin -->
    <gazebo>
      <plugin name="${namespace}_kinematics_plugin"
              filename="libuuv_kinematics_ros_plugin.so">
      </plugin>
    </gazebo>

    <gazebo>
      <plugin name="gazebo_ros_control" filename="libgazebo_ros_control.so">
        <robotNamespace>/${namespace}</robotNamespace>
        <robotParam>/${namespace}/robot_description</robotParam>

        <bathymetry>
          <interval_s>1.0</interval_s>
        </bathymetry>

      </plugin>
    </gazebo>

    <xacro:include filename="$(find uuv_kinematics_description)/urdf/uuv_kinematics_sensors.xacro"/>

  </xacro:macro>
</robot>
